Traceback (most recent call last):
  File "/opt/homebrew/Caskroom/miniconda/base/envs/python310/lib/python3.10/site-packages/jupyter_cache/executors/utils.py", line 58, in single_nb_execution
    executenb(
  File "/opt/homebrew/Caskroom/miniconda/base/envs/python310/lib/python3.10/site-packages/nbclient/client.py", line 1204, in execute
    return NotebookClient(nb=nb, resources=resources, km=km, **kwargs).execute()
  File "/opt/homebrew/Caskroom/miniconda/base/envs/python310/lib/python3.10/site-packages/nbclient/util.py", line 84, in wrapped
    return just_run(coro(*args, **kwargs))
  File "/opt/homebrew/Caskroom/miniconda/base/envs/python310/lib/python3.10/site-packages/nbclient/util.py", line 62, in just_run
    return loop.run_until_complete(coro)
  File "/opt/homebrew/Caskroom/miniconda/base/envs/python310/lib/python3.10/asyncio/base_events.py", line 649, in run_until_complete
    return future.result()
  File "/opt/homebrew/Caskroom/miniconda/base/envs/python310/lib/python3.10/site-packages/nbclient/client.py", line 663, in async_execute
    await self.async_execute_cell(
  File "/opt/homebrew/Caskroom/miniconda/base/envs/python310/lib/python3.10/site-packages/nbclient/client.py", line 965, in async_execute_cell
    await self._check_raise_for_error(cell, cell_index, exec_reply)
  File "/opt/homebrew/Caskroom/miniconda/base/envs/python310/lib/python3.10/site-packages/nbclient/client.py", line 862, in _check_raise_for_error
    raise CellExecutionError.from_cell_and_msg(cell, exec_reply_content)
nbclient.exceptions.CellExecutionError: An error occurred while executing the following cell:
------------------
gitter_y = model.predict(np.stack([gitter_x1.ravel(),gitter_x2.ravel()]).T)

  fig = go.Figure()
  fig.add_trace(go.Scatter(x = gitter_x1.ravel(), y = gitter_x2.ravel(), 
                            marker_color=gitter_y.ravel(), mode='markers', opacity=0.1, name='Gitter'))
  fig.add_trace(go.Scatter(x = X[:,0], y = X[:,1], mode='markers', marker_color=y, name='Daten'))
  fig.update_layout(
    title='Random Forest',
    xaxis_title = 'Feature 1',
    yaxis_title = 'Feature 2'
  )
  fig.show()
------------------

[0;36m  Cell [0;32mIn[6], line 3[0;36m[0m
[0;31m    fig = go.Figure()[0m
[0m    ^[0m
[0;31mIndentationError[0m[0;31m:[0m unexpected indent

IndentationError: unexpected indent (2706444393.py, line 3)

