Traceback (most recent call last):
  File "/opt/homebrew/anaconda3/envs/python39/lib/python3.9/site-packages/jupyter_cache/executors/utils.py", line 51, in single_nb_execution
    executenb(
  File "/opt/homebrew/anaconda3/envs/python39/lib/python3.9/site-packages/nbclient/client.py", line 1204, in execute
    return NotebookClient(nb=nb, resources=resources, km=km, **kwargs).execute()
  File "/opt/homebrew/anaconda3/envs/python39/lib/python3.9/site-packages/nbclient/util.py", line 84, in wrapped
    return just_run(coro(*args, **kwargs))
  File "/opt/homebrew/anaconda3/envs/python39/lib/python3.9/site-packages/nbclient/util.py", line 62, in just_run
    return loop.run_until_complete(coro)
  File "/opt/homebrew/anaconda3/envs/python39/lib/python3.9/asyncio/base_events.py", line 642, in run_until_complete
    return future.result()
  File "/opt/homebrew/anaconda3/envs/python39/lib/python3.9/site-packages/nbclient/client.py", line 663, in async_execute
    await self.async_execute_cell(
  File "/opt/homebrew/anaconda3/envs/python39/lib/python3.9/site-packages/nbclient/client.py", line 965, in async_execute_cell
    await self._check_raise_for_error(cell, cell_index, exec_reply)
  File "/opt/homebrew/anaconda3/envs/python39/lib/python3.9/site-packages/nbclient/client.py", line 862, in _check_raise_for_error
    raise CellExecutionError.from_cell_and_msg(cell, exec_reply_content)
nbclient.exceptions.CellExecutionError: An error occurred while executing the following cell:
------------------
import plotly.express as px
from jupyter_dash import JupyterDash
from dash import dcc
from dash import html
from dash.dependencies import Input, Output
# Load Data
df = px.data.tips()
# Build App
app = JupyterDash(__name__)
app.layout = html.Div([
    html.H1("JupyterDash Demo"),
    dcc.Graph(id='graph'),
    html.Label([
        "colorscale",
        dcc.Dropdown(
            id='colorscale-dropdown', clearable=False,
            value='plasma', options=[
                {'label': c, 'value': c}
                for c in px.colors.named_colorscales()
            ])
    ]),
])
# Define callback to update graph
@app.callback(
    Output('graph', 'figure'),
    [Input("colorscale-dropdown", "value")]
)
def update_figure(colorscale):
    return px.scatter(
        df, x="total_bill", y="tip", color="size",
        color_continuous_scale=colorscale,
        render_mode="webgl", title="Tips"
    )
# Run app and display result inline in the notebook
app.run_server(mode='inline')
------------------

[0;31m---------------------------------------------------------------------------[0m
[0;31mOSError[0m                                   Traceback (most recent call last)
Input [0;32mIn [4][0m, in [0;36m<cell line: 35>[0;34m()[0m
[1;32m     29[0m     [38;5;28;01mreturn[39;00m px[38;5;241m.[39mscatter(
[1;32m     30[0m         df, x[38;5;241m=[39m[38;5;124m"[39m[38;5;124mtotal_bill[39m[38;5;124m"[39m, y[38;5;241m=[39m[38;5;124m"[39m[38;5;124mtip[39m[38;5;124m"[39m, color[38;5;241m=[39m[38;5;124m"[39m[38;5;124msize[39m[38;5;124m"[39m,
[1;32m     31[0m         color_continuous_scale[38;5;241m=[39mcolorscale,
[1;32m     32[0m         render_mode[38;5;241m=[39m[38;5;124m"[39m[38;5;124mwebgl[39m[38;5;124m"[39m, title[38;5;241m=[39m[38;5;124m"[39m[38;5;124mTips[39m[38;5;124m"[39m
[1;32m     33[0m     )
[1;32m     34[0m [38;5;66;03m# Run app and display result inline in the notebook[39;00m
[0;32m---> 35[0m [43mapp[49m[38;5;241;43m.[39;49m[43mrun_server[49m[43m([49m[43mmode[49m[38;5;241;43m=[39;49m[38;5;124;43m'[39;49m[38;5;124;43minline[39;49m[38;5;124;43m'[39;49m[43m)[49m

File [0;32m/opt/homebrew/anaconda3/envs/python39/lib/python3.9/site-packages/jupyter_dash/jupyter_app.py:322[0m, in [0;36mJupyterDash.run_server[0;34m(self, mode, width, height, inline_exceptions, **kwargs)[0m
[1;32m    312[0m         url [38;5;241m=[39m [38;5;124m"[39m[38;5;124mhttp://[39m[38;5;132;01m{host}[39;00m[38;5;124m:[39m[38;5;132;01m{port}[39;00m[38;5;124m"[39m[38;5;241m.[39mformat(
[1;32m    313[0m             host[38;5;241m=[39mhost, port[38;5;241m=[39mport, token[38;5;241m=[39mJupyterDash[38;5;241m.[39m_token
[1;32m    314[0m         )
[1;32m    315[0m         [38;5;28;01mraise[39;00m [38;5;167;01mOSError[39;00m(
[1;32m    316[0m             [38;5;124m"[39m[38;5;124mAddress [39m[38;5;124m'[39m[38;5;132;01m{url}[39;00m[38;5;124m'[39m[38;5;124m already in use.[39m[38;5;130;01m\n[39;00m[38;5;124m"[39m
[1;32m    317[0m             [38;5;124m"[39m[38;5;124m    Try passing a different port to run_server.[39m[38;5;124m"[39m[38;5;241m.[39mformat(
[1;32m    318[0m                 url[38;5;241m=[39murl
[1;32m    319[0m             )
[1;32m    320[0m         )
[0;32m--> 322[0m [43mwait_for_app[49m[43m([49m[43m)[49m
[1;32m    324[0m [38;5;28;01mif[39;00m JupyterDash[38;5;241m.[39m_in_colab:
[1;32m    325[0m     [38;5;28mself[39m[38;5;241m.[39m_display_in_colab(dashboard_url, port, mode, width, height)

File [0;32m/opt/homebrew/anaconda3/envs/python39/lib/python3.9/site-packages/retrying.py:49[0m, in [0;36mretry.<locals>.wrap.<locals>.wrapped_f[0;34m(*args, **kw)[0m
[1;32m     47[0m [38;5;129m@six[39m[38;5;241m.[39mwraps(f)
[1;32m     48[0m [38;5;28;01mdef[39;00m [38;5;21mwrapped_f[39m([38;5;241m*[39margs, [38;5;241m*[39m[38;5;241m*[39mkw):
[0;32m---> 49[0m     [38;5;28;01mreturn[39;00m [43mRetrying[49m[43m([49m[38;5;241;43m*[39;49m[43mdargs[49m[43m,[49m[43m [49m[38;5;241;43m*[39;49m[38;5;241;43m*[39;49m[43mdkw[49m[43m)[49m[38;5;241;43m.[39;49m[43mcall[49m[43m([49m[43mf[49m[43m,[49m[43m [49m[38;5;241;43m*[39;49m[43margs[49m[43m,[49m[43m [49m[38;5;241;43m*[39;49m[38;5;241;43m*[39;49m[43mkw[49m[43m)[49m

File [0;32m/opt/homebrew/anaconda3/envs/python39/lib/python3.9/site-packages/retrying.py:212[0m, in [0;36mRetrying.call[0;34m(self, fn, *args, **kwargs)[0m
[1;32m    209[0m [38;5;28;01mif[39;00m [38;5;28mself[39m[38;5;241m.[39mstop(attempt_number, delay_since_first_attempt_ms):
[1;32m    210[0m     [38;5;28;01mif[39;00m [38;5;129;01mnot[39;00m [38;5;28mself[39m[38;5;241m.[39m_wrap_exception [38;5;129;01mand[39;00m attempt[38;5;241m.[39mhas_exception:
[1;32m    211[0m         [38;5;66;03m# get() on an attempt with an exception should cause it to be raised, but raise just in case[39;00m
[0;32m--> 212[0m         [38;5;28;01mraise[39;00m [43mattempt[49m[38;5;241;43m.[39;49m[43mget[49m[43m([49m[43m)[49m
[1;32m    213[0m     [38;5;28;01melse[39;00m:
[1;32m    214[0m         [38;5;28;01mraise[39;00m RetryError(attempt)

File [0;32m/opt/homebrew/anaconda3/envs/python39/lib/python3.9/site-packages/retrying.py:247[0m, in [0;36mAttempt.get[0;34m(self, wrap_exception)[0m
[1;32m    245[0m         [38;5;28;01mraise[39;00m RetryError([38;5;28mself[39m)
[1;32m    246[0m     [38;5;28;01melse[39;00m:
[0;32m--> 247[0m         [43msix[49m[38;5;241;43m.[39;49m[43mreraise[49m[43m([49m[38;5;28;43mself[39;49m[38;5;241;43m.[39;49m[43mvalue[49m[43m[[49m[38;5;241;43m0[39;49m[43m][49m[43m,[49m[43m [49m[38;5;28;43mself[39;49m[38;5;241;43m.[39;49m[43mvalue[49m[43m[[49m[38;5;241;43m1[39;49m[43m][49m[43m,[49m[43m [49m[38;5;28;43mself[39;49m[38;5;241;43m.[39;49m[43mvalue[49m[43m[[49m[38;5;241;43m2[39;49m[43m][49m[43m)[49m
[1;32m    248[0m [38;5;28;01melse[39;00m:
[1;32m    249[0m     [38;5;28;01mreturn[39;00m [38;5;28mself[39m[38;5;241m.[39mvalue

File [0;32m/opt/homebrew/anaconda3/envs/python39/lib/python3.9/site-packages/six.py:719[0m, in [0;36mreraise[0;34m(tp, value, tb)[0m
[1;32m    717[0m     [38;5;28;01mif[39;00m value[38;5;241m.[39m__traceback__ [38;5;129;01mis[39;00m [38;5;129;01mnot[39;00m tb:
[1;32m    718[0m         [38;5;28;01mraise[39;00m value[38;5;241m.[39mwith_traceback(tb)
[0;32m--> 719[0m     [38;5;28;01mraise[39;00m value
[1;32m    720[0m [38;5;28;01mfinally[39;00m:
[1;32m    721[0m     value [38;5;241m=[39m [38;5;28;01mNone[39;00m

File [0;32m/opt/homebrew/anaconda3/envs/python39/lib/python3.9/site-packages/retrying.py:200[0m, in [0;36mRetrying.call[0;34m(self, fn, *args, **kwargs)[0m
[1;32m    198[0m [38;5;28;01mwhile[39;00m [38;5;28;01mTrue[39;00m:
[1;32m    199[0m     [38;5;28;01mtry[39;00m:
[0;32m--> 200[0m         attempt [38;5;241m=[39m Attempt([43mfn[49m[43m([49m[38;5;241;43m*[39;49m[43margs[49m[43m,[49m[43m [49m[38;5;241;43m*[39;49m[38;5;241;43m*[39;49m[43mkwargs[49m[43m)[49m, attempt_number, [38;5;28;01mFalse[39;00m)
[1;32m    201[0m     [38;5;28;01mexcept[39;00m:
[1;32m    202[0m         tb [38;5;241m=[39m sys[38;5;241m.[39mexc_info()

File [0;32m/opt/homebrew/anaconda3/envs/python39/lib/python3.9/site-packages/jupyter_dash/jupyter_app.py:315[0m, in [0;36mJupyterDash.run_server.<locals>.wait_for_app[0;34m()[0m
[1;32m    311[0m [38;5;28;01mif[39;00m res [38;5;241m!=[39m [38;5;124m"[39m[38;5;124mAlive[39m[38;5;124m"[39m:
[1;32m    312[0m     url [38;5;241m=[39m [38;5;124m"[39m[38;5;124mhttp://[39m[38;5;132;01m{host}[39;00m[38;5;124m:[39m[38;5;132;01m{port}[39;00m[38;5;124m"[39m[38;5;241m.[39mformat(
[1;32m    313[0m         host[38;5;241m=[39mhost, port[38;5;241m=[39mport, token[38;5;241m=[39mJupyterDash[38;5;241m.[39m_token
[1;32m    314[0m     )
[0;32m--> 315[0m     [38;5;28;01mraise[39;00m [38;5;167;01mOSError[39;00m(
[1;32m    316[0m         [38;5;124m"[39m[38;5;124mAddress [39m[38;5;124m'[39m[38;5;132;01m{url}[39;00m[38;5;124m'[39m[38;5;124m already in use.[39m[38;5;130;01m\n[39;00m[38;5;124m"[39m
[1;32m    317[0m         [38;5;124m"[39m[38;5;124m    Try passing a different port to run_server.[39m[38;5;124m"[39m[38;5;241m.[39mformat(
[1;32m    318[0m             url[38;5;241m=[39murl
[1;32m    319[0m         )
[1;32m    320[0m     )

[0;31mOSError[0m: Address 'http://127.0.0.1:8050' already in use.
    Try passing a different port to run_server.
OSError: Address 'http://127.0.0.1:8050' already in use.
    Try passing a different port to run_server.

