Traceback (most recent call last):
  File "/opt/homebrew/anaconda3/envs/python39/lib/python3.9/site-packages/jupyter_cache/executors/utils.py", line 51, in single_nb_execution
    executenb(
  File "/opt/homebrew/anaconda3/envs/python39/lib/python3.9/site-packages/nbclient/client.py", line 1204, in execute
    return NotebookClient(nb=nb, resources=resources, km=km, **kwargs).execute()
  File "/opt/homebrew/anaconda3/envs/python39/lib/python3.9/site-packages/nbclient/util.py", line 84, in wrapped
    return just_run(coro(*args, **kwargs))
  File "/opt/homebrew/anaconda3/envs/python39/lib/python3.9/site-packages/nbclient/util.py", line 62, in just_run
    return loop.run_until_complete(coro)
  File "/opt/homebrew/anaconda3/envs/python39/lib/python3.9/asyncio/base_events.py", line 647, in run_until_complete
    return future.result()
  File "/opt/homebrew/anaconda3/envs/python39/lib/python3.9/site-packages/nbclient/client.py", line 663, in async_execute
    await self.async_execute_cell(
  File "/opt/homebrew/anaconda3/envs/python39/lib/python3.9/site-packages/nbclient/client.py", line 965, in async_execute_cell
    await self._check_raise_for_error(cell, cell_index, exec_reply)
  File "/opt/homebrew/anaconda3/envs/python39/lib/python3.9/site-packages/nbclient/client.py", line 862, in _check_raise_for_error
    raise CellExecutionError.from_cell_and_msg(cell, exec_reply_content)
nbclient.exceptions.CellExecutionError: An error occurred while executing the following cell:
------------------
# erzeuge k√ºnstliche Daten
X,y = erzeuge_kuenstliche_messdaten([-3, 7, 2, -2], 30)

# Split in Trainings- und Testdaten
from sklearn.model_selection import train_test_split
X_train, X_test, y_train, y_test = train_test_split(X,y)

# Auswahl des Modells 
from sklearn.linear_model import LinearRegression
model = LinearRegression()

# Training 
model.fit(X_train, y_train)
print('k0 = {}'.format(model.intercept_))
print('k1 = {}'.format(model.coef_))

# Validierung
from sklearn.metrics import r2_score
r2_train = r2_score(y_train, model.predict(X_train))
r2_test  = r2_score(y_test,  model.predict(X_test))
print('R2-Score der Trainingsdaten: {:.4}'.format(r2_train))
print('R2-Score der Testdaten: {:.4}'.format(r2_test))

# Visualisierung
X_vis = np.linspace(-5,5,100).reshape(-1,1)
y_vis = model.predict(X_vis)

fig, ax = plt.subplots(figsize=(12,9))
ax.scatter(X_train, y_train, label='train')
ax.scatter(X_test, y_test, label='test')
ax.plot(X_vis, y_vis, '--k')
ax.legend();
------------------

[0;31m---------------------------------------------------------------------------[0m
[0;31mNameError[0m                                 Traceback (most recent call last)
Input [0;32mIn [2][0m, in [0;36m<cell line: 28>[0;34m()[0m
[1;32m     25[0m X_vis [38;5;241m=[39m np[38;5;241m.[39mlinspace([38;5;241m-[39m[38;5;241m5[39m,[38;5;241m5[39m,[38;5;241m100[39m)[38;5;241m.[39mreshape([38;5;241m-[39m[38;5;241m1[39m,[38;5;241m1[39m)
[1;32m     26[0m y_vis [38;5;241m=[39m model[38;5;241m.[39mpredict(X_vis)
[0;32m---> 28[0m fig, ax [38;5;241m=[39m [43mplt[49m[38;5;241m.[39msubplots(figsize[38;5;241m=[39m([38;5;241m12[39m,[38;5;241m9[39m))
[1;32m     29[0m ax[38;5;241m.[39mscatter(X_train, y_train, label[38;5;241m=[39m[38;5;124m'[39m[38;5;124mtrain[39m[38;5;124m'[39m)
[1;32m     30[0m ax[38;5;241m.[39mscatter(X_test, y_test, label[38;5;241m=[39m[38;5;124m'[39m[38;5;124mtest[39m[38;5;124m'[39m)

[0;31mNameError[0m: name 'plt' is not defined
NameError: name 'plt' is not defined

