Traceback (most recent call last):
  File "/opt/homebrew/Caskroom/miniconda/base/envs/python311/lib/python3.11/site-packages/jupyter_cache/executors/utils.py", line 58, in single_nb_execution
    executenb(
  File "/opt/homebrew/Caskroom/miniconda/base/envs/python311/lib/python3.11/site-packages/nbclient/client.py", line 1204, in execute
    return NotebookClient(nb=nb, resources=resources, km=km, **kwargs).execute()
           ^^^^^^^^^^^^^^^^^^^^^^^^^^^^^^^^^^^^^^^^^^^^^^^^^^^^^^^^^^^^^^^^^^^^^
  File "/opt/homebrew/Caskroom/miniconda/base/envs/python311/lib/python3.11/site-packages/nbclient/util.py", line 84, in wrapped
    return just_run(coro(*args, **kwargs))
           ^^^^^^^^^^^^^^^^^^^^^^^^^^^^^^^
  File "/opt/homebrew/Caskroom/miniconda/base/envs/python311/lib/python3.11/site-packages/nbclient/util.py", line 62, in just_run
    return loop.run_until_complete(coro)
           ^^^^^^^^^^^^^^^^^^^^^^^^^^^^^
  File "/opt/homebrew/Caskroom/miniconda/base/envs/python311/lib/python3.11/asyncio/base_events.py", line 650, in run_until_complete
    return future.result()
           ^^^^^^^^^^^^^^^
  File "/opt/homebrew/Caskroom/miniconda/base/envs/python311/lib/python3.11/contextlib.py", line 222, in __aexit__
    await self.gen.athrow(typ, value, traceback)
  File "/opt/homebrew/Caskroom/miniconda/base/envs/python311/lib/python3.11/site-packages/nbclient/client.py", line 608, in async_setup_kernel
    yield
  File "/opt/homebrew/Caskroom/miniconda/base/envs/python311/lib/python3.11/site-packages/nbclient/client.py", line 663, in async_execute
    await self.async_execute_cell(
  File "/opt/homebrew/Caskroom/miniconda/base/envs/python311/lib/python3.11/site-packages/nbclient/client.py", line 965, in async_execute_cell
    await self._check_raise_for_error(cell, cell_index, exec_reply)
  File "/opt/homebrew/Caskroom/miniconda/base/envs/python311/lib/python3.11/site-packages/nbclient/client.py", line 862, in _check_raise_for_error
    raise CellExecutionError.from_cell_and_msg(cell, exec_reply_content)
nbclient.exceptions.CellExecutionError: An error occurred while executing the following cell:
------------------
# Laden der Karte  
karte = folium.Map(location=[50.110880, 8.679490], zoom_start=13, tiles='StamenTerrain')

# Anzeige der Karte
karte
------------------

[0;31m---------------------------------------------------------------------------[0m
[0;31mValueError[0m                                Traceback (most recent call last)
Cell [0;32mIn[3], line 2[0m
[1;32m      1[0m [38;5;66;03m# Laden der Karte  [39;00m
[0;32m----> 2[0m karte [38;5;241m=[39m folium[38;5;241m.[39mMap(location[38;5;241m=[39m[[38;5;241m50.110880[39m, [38;5;241m8.679490[39m], zoom_start[38;5;241m=[39m[38;5;241m13[39m, tiles[38;5;241m=[39m[38;5;124m'[39m[38;5;124mStamenTerrain[39m[38;5;124m'[39m)
[1;32m      4[0m [38;5;66;03m# Anzeige der Karte[39;00m
[1;32m      5[0m karte

File [0;32m/opt/homebrew/Caskroom/miniconda/base/envs/python311/lib/python3.11/site-packages/folium/folium.py:308[0m, in [0;36mMap.__init__[0;34m(self, location, width, height, left, top, position, tiles, attr, min_zoom, max_zoom, zoom_start, min_lat, max_lat, min_lon, max_lon, max_bounds, crs, control_scale, prefer_canvas, no_touch, disable_3d, png_enabled, zoom_control, font_size, **kwargs)[0m
[1;32m    306[0m     [38;5;28mself[39m[38;5;241m.[39madd_child(tiles)
[1;32m    307[0m [38;5;28;01melif[39;00m tiles:
[0;32m--> 308[0m     tile_layer [38;5;241m=[39m TileLayer(
[1;32m    309[0m         tiles[38;5;241m=[39mtiles, attr[38;5;241m=[39mattr, min_zoom[38;5;241m=[39mmin_zoom, max_zoom[38;5;241m=[39mmax_zoom
[1;32m    310[0m     )
[1;32m    311[0m     [38;5;28mself[39m[38;5;241m.[39madd_child(tile_layer, name[38;5;241m=[39mtile_layer[38;5;241m.[39mtile_name)

File [0;32m/opt/homebrew/Caskroom/miniconda/base/envs/python311/lib/python3.11/site-packages/folium/raster_layers.py:140[0m, in [0;36mTileLayer.__init__[0;34m(self, tiles, min_zoom, max_zoom, max_native_zoom, attr, detect_retina, name, overlay, control, show, no_wrap, subdomains, tms, opacity, **kwargs)[0m
[1;32m    138[0m [38;5;28mself[39m[38;5;241m.[39mtiles [38;5;241m=[39m tiles
[1;32m    139[0m [38;5;28;01mif[39;00m [38;5;129;01mnot[39;00m attr:
[0;32m--> 140[0m     [38;5;28;01mraise[39;00m [38;5;167;01mValueError[39;00m([38;5;124m"[39m[38;5;124mCustom tiles must have an attribution.[39m[38;5;124m"[39m)
[1;32m    142[0m [38;5;28mself[39m[38;5;241m.[39moptions [38;5;241m=[39m parse_options(
[1;32m    143[0m     min_zoom[38;5;241m=[39mmin_zoom,
[1;32m    144[0m     max_zoom[38;5;241m=[39mmax_zoom,
[0;32m   (...)[0m
[1;32m    152[0m     [38;5;241m*[39m[38;5;241m*[39mkwargs,
[1;32m    153[0m )

[0;31mValueError[0m: Custom tiles must have an attribution.
ValueError: Custom tiles must have an attribution.

