Traceback (most recent call last):
  File "/opt/homebrew/Caskroom/miniconda/base/envs/python310/lib/python3.10/site-packages/jupyter_cache/executors/utils.py", line 58, in single_nb_execution
    executenb(
  File "/opt/homebrew/Caskroom/miniconda/base/envs/python310/lib/python3.10/site-packages/nbclient/client.py", line 1204, in execute
    return NotebookClient(nb=nb, resources=resources, km=km, **kwargs).execute()
  File "/opt/homebrew/Caskroom/miniconda/base/envs/python310/lib/python3.10/site-packages/nbclient/util.py", line 84, in wrapped
    return just_run(coro(*args, **kwargs))
  File "/opt/homebrew/Caskroom/miniconda/base/envs/python310/lib/python3.10/site-packages/nbclient/util.py", line 62, in just_run
    return loop.run_until_complete(coro)
  File "/opt/homebrew/Caskroom/miniconda/base/envs/python310/lib/python3.10/asyncio/base_events.py", line 649, in run_until_complete
    return future.result()
  File "/opt/homebrew/Caskroom/miniconda/base/envs/python310/lib/python3.10/site-packages/nbclient/client.py", line 663, in async_execute
    await self.async_execute_cell(
  File "/opt/homebrew/Caskroom/miniconda/base/envs/python310/lib/python3.10/site-packages/nbclient/client.py", line 965, in async_execute_cell
    await self._check_raise_for_error(cell, cell_index, exec_reply)
  File "/opt/homebrew/Caskroom/miniconda/base/envs/python310/lib/python3.10/site-packages/nbclient/client.py", line 862, in _check_raise_for_error
    raise CellExecutionError.from_cell_and_msg(cell, exec_reply_content)
nbclient.exceptions.CellExecutionError: An error occurred while executing the following cell:
------------------
import numpy as np

sigma_z = np.linspace(0, 1)[1:]
cost_1 = - np.log(sigma_z)

fig = px.line(x = sigma_z, y = cost_1,
              title='Kostenfunktion, falls Klasse 1 korrekt (y=1)',
              labels={'x': 'sigma(z)', 'y': 'Kosten c_1'})
fig.show()
------------------

[0;31m---------------------------------------------------------------------------[0m
[0;31mNameError[0m                                 Traceback (most recent call last)
Cell [0;32mIn[1], line 6[0m
[1;32m      3[0m sigma_z [38;5;241m=[39m np[38;5;241m.[39mlinspace([38;5;241m0[39m, [38;5;241m1[39m)[[38;5;241m1[39m:]
[1;32m      4[0m cost_1 [38;5;241m=[39m [38;5;241m-[39m np[38;5;241m.[39mlog(sigma_z)
[0;32m----> 6[0m fig [38;5;241m=[39m [43mpx[49m[38;5;241m.[39mline(x [38;5;241m=[39m sigma_z, y [38;5;241m=[39m cost_1,
[1;32m      7[0m               title[38;5;241m=[39m[38;5;124m'[39m[38;5;124mKostenfunktion, falls Klasse 1 korrekt (y=1)[39m[38;5;124m'[39m,
[1;32m      8[0m               labels[38;5;241m=[39m{[38;5;124m'[39m[38;5;124mx[39m[38;5;124m'[39m: [38;5;124m'[39m[38;5;124msigma(z)[39m[38;5;124m'[39m, [38;5;124m'[39m[38;5;124my[39m[38;5;124m'[39m: [38;5;124m'[39m[38;5;124mKosten c_1[39m[38;5;124m'[39m})
[1;32m      9[0m fig[38;5;241m.[39mshow()

[0;31mNameError[0m: name 'px' is not defined
NameError: name 'px' is not defined

