Traceback (most recent call last):
  File "/opt/homebrew/Caskroom/miniconda/base/envs/python310/lib/python3.10/site-packages/jupyter_cache/executors/utils.py", line 58, in single_nb_execution
    executenb(
  File "/opt/homebrew/Caskroom/miniconda/base/envs/python310/lib/python3.10/site-packages/nbclient/client.py", line 1204, in execute
    return NotebookClient(nb=nb, resources=resources, km=km, **kwargs).execute()
  File "/opt/homebrew/Caskroom/miniconda/base/envs/python310/lib/python3.10/site-packages/nbclient/util.py", line 84, in wrapped
    return just_run(coro(*args, **kwargs))
  File "/opt/homebrew/Caskroom/miniconda/base/envs/python310/lib/python3.10/site-packages/nbclient/util.py", line 62, in just_run
    return loop.run_until_complete(coro)
  File "/opt/homebrew/Caskroom/miniconda/base/envs/python310/lib/python3.10/asyncio/base_events.py", line 649, in run_until_complete
    return future.result()
  File "/opt/homebrew/Caskroom/miniconda/base/envs/python310/lib/python3.10/site-packages/nbclient/client.py", line 663, in async_execute
    await self.async_execute_cell(
  File "/opt/homebrew/Caskroom/miniconda/base/envs/python310/lib/python3.10/site-packages/nbclient/client.py", line 965, in async_execute_cell
    await self._check_raise_for_error(cell, cell_index, exec_reply)
  File "/opt/homebrew/Caskroom/miniconda/base/envs/python310/lib/python3.10/site-packages/nbclient/client.py", line 862, in _check_raise_for_error
    raise CellExecutionError.from_cell_and_msg(cell, exec_reply_content)
nbclient.exceptions.CellExecutionError: An error occurred while executing the following cell:
------------------
fig3 = px.scatter(data_dritte_liga, x = 'Wert', y = 'Ligazugeh√∂rigkeit')
fig2 = px.scatter(data_zweite_liga, x = 'Wert', y = 'Ligazugeh√∂rigkeit')
fig_model = px.line(x = x, y = sigma_z)

import plotly.express as px
import plotly.graph_objects as go

fig = go.Figure(fig_model.data + fig2.data + fig3.data)
fig.update_layout(title='Klassifikation 2. Bundesliga / 3. Liga',
                  xaxis_title='Marktwert',
                  yaxis_title='Ligazugeh√∂rigkeit')
fig.show()
------------------

[0;31m---------------------------------------------------------------------------[0m
[0;31mNameError[0m                                 Traceback (most recent call last)
Cell [0;32mIn[8], line 1[0m
[0;32m----> 1[0m fig3 [38;5;241m=[39m [43mpx[49m[38;5;241m.[39mscatter(data_dritte_liga, x [38;5;241m=[39m [38;5;124m'[39m[38;5;124mWert[39m[38;5;124m'[39m, y [38;5;241m=[39m [38;5;124m'[39m[38;5;124mLigazugeh√∂rigkeit[39m[38;5;124m'[39m)
[1;32m      2[0m fig2 [38;5;241m=[39m px[38;5;241m.[39mscatter(data_zweite_liga, x [38;5;241m=[39m [38;5;124m'[39m[38;5;124mWert[39m[38;5;124m'[39m, y [38;5;241m=[39m [38;5;124m'[39m[38;5;124mLigazugeh√∂rigkeit[39m[38;5;124m'[39m)
[1;32m      3[0m fig_model [38;5;241m=[39m px[38;5;241m.[39mline(x [38;5;241m=[39m x, y [38;5;241m=[39m sigma_z)

[0;31mNameError[0m: name 'px' is not defined
NameError: name 'px' is not defined

