Traceback (most recent call last):
  File "/opt/homebrew/Caskroom/miniconda/base/envs/python312/lib/python3.12/site-packages/jupyter_cache/executors/utils.py", line 58, in single_nb_execution
    executenb(
  File "/opt/homebrew/Caskroom/miniconda/base/envs/python312/lib/python3.12/site-packages/nbclient/client.py", line 1314, in execute
    return NotebookClient(nb=nb, resources=resources, km=km, **kwargs).execute()
           ^^^^^^^^^^^^^^^^^^^^^^^^^^^^^^^^^^^^^^^^^^^^^^^^^^^^^^^^^^^^^^^^^^^^^
  File "/opt/homebrew/Caskroom/miniconda/base/envs/python312/lib/python3.12/site-packages/jupyter_core/utils/__init__.py", line 165, in wrapped
    return loop.run_until_complete(inner)
           ^^^^^^^^^^^^^^^^^^^^^^^^^^^^^^
  File "/opt/homebrew/Caskroom/miniconda/base/envs/python312/lib/python3.12/asyncio/base_events.py", line 685, in run_until_complete
    return future.result()
           ^^^^^^^^^^^^^^^
  File "/opt/homebrew/Caskroom/miniconda/base/envs/python312/lib/python3.12/site-packages/nbclient/client.py", line 709, in async_execute
    await self.async_execute_cell(
  File "/opt/homebrew/Caskroom/miniconda/base/envs/python312/lib/python3.12/site-packages/nbclient/client.py", line 1062, in async_execute_cell
    await self._check_raise_for_error(cell, cell_index, exec_reply)
  File "/opt/homebrew/Caskroom/miniconda/base/envs/python312/lib/python3.12/site-packages/nbclient/client.py", line 918, in _check_raise_for_error
    raise CellExecutionError.from_cell_and_msg(cell, exec_reply_content)
nbclient.exceptions.CellExecutionError: An error occurred while executing the following cell:
------------------
modell.fit(X_train, y_train, eval_set=[(X_train, y_train), (X_test, y_test)],     
    early_stopping_rounds=10, verbose=False)
------------------


[0;31m---------------------------------------------------------------------------[0m
[0;31mTypeError[0m                                 Traceback (most recent call last)
Cell [0;32mIn[13], line 1[0m
[0;32m----> 1[0m [43mmodell[49m[38;5;241;43m.[39;49m[43mfit[49m[43m([49m[43mX_train[49m[43m,[49m[43m [49m[43my_train[49m[43m,[49m[43m [49m[43meval_set[49m[38;5;241;43m=[39;49m[43m[[49m[43m([49m[43mX_train[49m[43m,[49m[43m [49m[43my_train[49m[43m)[49m[43m,[49m[43m [49m[43m([49m[43mX_test[49m[43m,[49m[43m [49m[43my_test[49m[43m)[49m[43m][49m[43m,[49m[43m     [49m
[1;32m      2[0m [43m    [49m[43mearly_stopping_rounds[49m[38;5;241;43m=[39;49m[38;5;241;43m10[39;49m[43m,[49m[43m [49m[43mverbose[49m[38;5;241;43m=[39;49m[38;5;28;43;01mFalse[39;49;00m[43m)[49m

File [0;32m/opt/homebrew/Caskroom/miniconda/base/envs/python312/lib/python3.12/site-packages/xgboost/core.py:726[0m, in [0;36mrequire_keyword_args.<locals>.throw_if.<locals>.inner_f[0;34m(*args, **kwargs)[0m
[1;32m    724[0m [38;5;28;01mfor[39;00m k, arg [38;5;129;01min[39;00m [38;5;28mzip[39m(sig[38;5;241m.[39mparameters, args):
[1;32m    725[0m     kwargs[k] [38;5;241m=[39m arg
[0;32m--> 726[0m [38;5;28;01mreturn[39;00m [43mfunc[49m[43m([49m[38;5;241;43m*[39;49m[38;5;241;43m*[39;49m[43mkwargs[49m[43m)[49m

[0;31mTypeError[0m: XGBClassifier.fit() got an unexpected keyword argument 'early_stopping_rounds'

