Traceback (most recent call last):
  File "/opt/homebrew/Caskroom/miniconda/base/envs/python311/lib/python3.11/site-packages/jupyter_cache/executors/utils.py", line 58, in single_nb_execution
    executenb(
  File "/opt/homebrew/Caskroom/miniconda/base/envs/python311/lib/python3.11/site-packages/nbclient/client.py", line 1204, in execute
    return NotebookClient(nb=nb, resources=resources, km=km, **kwargs).execute()
           ^^^^^^^^^^^^^^^^^^^^^^^^^^^^^^^^^^^^^^^^^^^^^^^^^^^^^^^^^^^^^^^^^^^^^
  File "/opt/homebrew/Caskroom/miniconda/base/envs/python311/lib/python3.11/site-packages/nbclient/util.py", line 84, in wrapped
    return just_run(coro(*args, **kwargs))
           ^^^^^^^^^^^^^^^^^^^^^^^^^^^^^^^
  File "/opt/homebrew/Caskroom/miniconda/base/envs/python311/lib/python3.11/site-packages/nbclient/util.py", line 62, in just_run
    return loop.run_until_complete(coro)
           ^^^^^^^^^^^^^^^^^^^^^^^^^^^^^
  File "/opt/homebrew/Caskroom/miniconda/base/envs/python311/lib/python3.11/asyncio/base_events.py", line 650, in run_until_complete
    return future.result()
           ^^^^^^^^^^^^^^^
  File "/opt/homebrew/Caskroom/miniconda/base/envs/python311/lib/python3.11/contextlib.py", line 222, in __aexit__
    await self.gen.athrow(typ, value, traceback)
  File "/opt/homebrew/Caskroom/miniconda/base/envs/python311/lib/python3.11/site-packages/nbclient/client.py", line 608, in async_setup_kernel
    yield
  File "/opt/homebrew/Caskroom/miniconda/base/envs/python311/lib/python3.11/site-packages/nbclient/client.py", line 663, in async_execute
    await self.async_execute_cell(
  File "/opt/homebrew/Caskroom/miniconda/base/envs/python311/lib/python3.11/site-packages/nbclient/client.py", line 965, in async_execute_cell
    await self._check_raise_for_error(cell, cell_index, exec_reply)
  File "/opt/homebrew/Caskroom/miniconda/base/envs/python311/lib/python3.11/site-packages/nbclient/client.py", line 862, in _check_raise_for_error
    raise CellExecutionError.from_cell_and_msg(cell, exec_reply_content)
nbclient.exceptions.CellExecutionError: An error occurred while executing the following cell:
------------------
import plotly.express as px
# plot artificial data
fig = px.scatter(daten, x = 'Kilometerstand [km]', y = 'Preis [EUR]', color=daten['verkauft'].astype(bool),
        title='KÃ¼nstliche Daten: Verkaufsaktion Autohaus',
        labels = {'x': 'Kilometerstand [km]', 'y': 'Preis [EUR]', 'color': 'verkauft'})
fig.show()
------------------

[0;31m---------------------------------------------------------------------------[0m
[0;31mNameError[0m                                 Traceback (most recent call last)
Cell [0;32mIn[2], line 3[0m
[1;32m      1[0m [38;5;28;01mimport[39;00m [38;5;21;01mplotly[39;00m[38;5;21;01m.[39;00m[38;5;21;01mexpress[39;00m [38;5;28;01mas[39;00m [38;5;21;01mpx[39;00m
[1;32m      2[0m [38;5;66;03m# plot artificial data[39;00m
[0;32m----> 3[0m fig [38;5;241m=[39m px[38;5;241m.[39mscatter(daten, x [38;5;241m=[39m [38;5;124m'[39m[38;5;124mKilometerstand [km][39m[38;5;124m'[39m, y [38;5;241m=[39m [38;5;124m'[39m[38;5;124mPreis [EUR][39m[38;5;124m'[39m, color[38;5;241m=[39mdaten[[38;5;124m'[39m[38;5;124mverkauft[39m[38;5;124m'[39m][38;5;241m.[39mastype([38;5;28mbool[39m),
[1;32m      4[0m         title[38;5;241m=[39m[38;5;124m'[39m[38;5;124mKÃ¼nstliche Daten: Verkaufsaktion Autohaus[39m[38;5;124m'[39m,
[1;32m      5[0m         labels [38;5;241m=[39m {[38;5;124m'[39m[38;5;124mx[39m[38;5;124m'[39m: [38;5;124m'[39m[38;5;124mKilometerstand [km][39m[38;5;124m'[39m, [38;5;124m'[39m[38;5;124my[39m[38;5;124m'[39m: [38;5;124m'[39m[38;5;124mPreis [EUR][39m[38;5;124m'[39m, [38;5;124m'[39m[38;5;124mcolor[39m[38;5;124m'[39m: [38;5;124m'[39m[38;5;124mverkauft[39m[38;5;124m'[39m})
[1;32m      6[0m fig[38;5;241m.[39mshow()

[0;31mNameError[0m: name 'daten' is not defined
NameError: name 'daten' is not defined

