Traceback (most recent call last):
  File "/opt/homebrew/Caskroom/miniconda/base/envs/python312/lib/python3.12/site-packages/jupyter_cache/executors/utils.py", line 58, in single_nb_execution
    executenb(
  File "/opt/homebrew/Caskroom/miniconda/base/envs/python312/lib/python3.12/site-packages/nbclient/client.py", line 1314, in execute
    return NotebookClient(nb=nb, resources=resources, km=km, **kwargs).execute()
           ^^^^^^^^^^^^^^^^^^^^^^^^^^^^^^^^^^^^^^^^^^^^^^^^^^^^^^^^^^^^^^^^^^^^^
  File "/opt/homebrew/Caskroom/miniconda/base/envs/python312/lib/python3.12/site-packages/jupyter_core/utils/__init__.py", line 165, in wrapped
    return loop.run_until_complete(inner)
           ^^^^^^^^^^^^^^^^^^^^^^^^^^^^^^
  File "/opt/homebrew/Caskroom/miniconda/base/envs/python312/lib/python3.12/asyncio/base_events.py", line 685, in run_until_complete
    return future.result()
           ^^^^^^^^^^^^^^^
  File "/opt/homebrew/Caskroom/miniconda/base/envs/python312/lib/python3.12/site-packages/nbclient/client.py", line 709, in async_execute
    await self.async_execute_cell(
  File "/opt/homebrew/Caskroom/miniconda/base/envs/python312/lib/python3.12/site-packages/nbclient/client.py", line 1062, in async_execute_cell
    await self._check_raise_for_error(cell, cell_index, exec_reply)
  File "/opt/homebrew/Caskroom/miniconda/base/envs/python312/lib/python3.12/site-packages/nbclient/client.py", line 918, in _check_raise_for_error
    raise CellExecutionError.from_cell_and_msg(cell, exec_reply_content)
nbclient.exceptions.CellExecutionError: An error occurred while executing the following cell:
------------------
df_train, df_test = train_test_split(df, test_size=2, random_state=0)

# visualization
fig1 = px.scatter(df_train, x = 'x', y = 'y', color_discrete_sequence=['red'])
fig2 = px.scatter(df_test,  x = 'x', y = 'y', color_discrete_sequence=['blue'])

import plotly.graph_objects as go 

fig = go.Figure(fig1.data + fig2.data)
fig.update_layout(
    title='KÃ¼nstlich generierte Daten'
)

fig.show()
------------------


[0;31m---------------------------------------------------------------------------[0m
[0;31mNameError[0m                                 Traceback (most recent call last)
Cell [0;32mIn[6], line 1[0m
[0;32m----> 1[0m df_train, df_test [38;5;241m=[39m train_test_split([43mdf[49m, test_size[38;5;241m=[39m[38;5;241m2[39m, random_state[38;5;241m=[39m[38;5;241m0[39m)
[1;32m      3[0m [38;5;66;03m# visualization[39;00m
[1;32m      4[0m fig1 [38;5;241m=[39m px[38;5;241m.[39mscatter(df_train, x [38;5;241m=[39m [38;5;124m'[39m[38;5;124mx[39m[38;5;124m'[39m, y [38;5;241m=[39m [38;5;124m'[39m[38;5;124my[39m[38;5;124m'[39m, color_discrete_sequence[38;5;241m=[39m[[38;5;124m'[39m[38;5;124mred[39m[38;5;124m'[39m])

[0;31mNameError[0m: name 'df' is not defined

