Traceback (most recent call last):
  File "/opt/homebrew/Caskroom/miniconda/base/envs/python311/lib/python3.11/site-packages/jupyter_cache/executors/utils.py", line 58, in single_nb_execution
    executenb(
  File "/opt/homebrew/Caskroom/miniconda/base/envs/python311/lib/python3.11/site-packages/nbclient/client.py", line 1204, in execute
    return NotebookClient(nb=nb, resources=resources, km=km, **kwargs).execute()
           ^^^^^^^^^^^^^^^^^^^^^^^^^^^^^^^^^^^^^^^^^^^^^^^^^^^^^^^^^^^^^^^^^^^^^
  File "/opt/homebrew/Caskroom/miniconda/base/envs/python311/lib/python3.11/site-packages/nbclient/util.py", line 84, in wrapped
    return just_run(coro(*args, **kwargs))
           ^^^^^^^^^^^^^^^^^^^^^^^^^^^^^^^
  File "/opt/homebrew/Caskroom/miniconda/base/envs/python311/lib/python3.11/site-packages/nbclient/util.py", line 62, in just_run
    return loop.run_until_complete(coro)
           ^^^^^^^^^^^^^^^^^^^^^^^^^^^^^
  File "/opt/homebrew/Caskroom/miniconda/base/envs/python311/lib/python3.11/asyncio/base_events.py", line 650, in run_until_complete
    return future.result()
           ^^^^^^^^^^^^^^^
  File "/opt/homebrew/Caskroom/miniconda/base/envs/python311/lib/python3.11/contextlib.py", line 222, in __aexit__
    await self.gen.athrow(typ, value, traceback)
  File "/opt/homebrew/Caskroom/miniconda/base/envs/python311/lib/python3.11/site-packages/nbclient/client.py", line 608, in async_setup_kernel
    yield
  File "/opt/homebrew/Caskroom/miniconda/base/envs/python311/lib/python3.11/site-packages/nbclient/client.py", line 663, in async_execute
    await self.async_execute_cell(
  File "/opt/homebrew/Caskroom/miniconda/base/envs/python311/lib/python3.11/site-packages/nbclient/client.py", line 965, in async_execute_cell
    await self._check_raise_for_error(cell, cell_index, exec_reply)
  File "/opt/homebrew/Caskroom/miniconda/base/envs/python311/lib/python3.11/site-packages/nbclient/client.py", line 862, in _check_raise_for_error
    raise CellExecutionError.from_cell_and_msg(cell, exec_reply_content)
nbclient.exceptions.CellExecutionError: An error occurred while executing the following cell:
------------------
if SAVE_IMAGES:
   #export_graphviz(model, 'entscheidungsbaum_autohaus.dot', feature_names=['Kilometerstand [km]', 'Preis [EUR]'], filled=True)
------------------

[0;36m  Cell [0;32mIn[9], line 2[0;36m[0m
[0;31m    #export_graphviz(model, 'entscheidungsbaum_autohaus.dot', feature_names=['Kilometerstand [km]', 'Preis [EUR]'], filled=True)[0m
[0m                                                                                                                                ^[0m
[0;31mSyntaxError[0m[0;31m:[0m incomplete input

SyntaxError: incomplete input (3123323882.py, line 2)

