Traceback (most recent call last):
  File "/opt/homebrew/Caskroom/miniconda/base/envs/python310/lib/python3.10/site-packages/jupyter_cache/executors/utils.py", line 58, in single_nb_execution
    executenb(
  File "/opt/homebrew/Caskroom/miniconda/base/envs/python310/lib/python3.10/site-packages/nbclient/client.py", line 1204, in execute
    return NotebookClient(nb=nb, resources=resources, km=km, **kwargs).execute()
  File "/opt/homebrew/Caskroom/miniconda/base/envs/python310/lib/python3.10/site-packages/nbclient/util.py", line 84, in wrapped
    return just_run(coro(*args, **kwargs))
  File "/opt/homebrew/Caskroom/miniconda/base/envs/python310/lib/python3.10/site-packages/nbclient/util.py", line 62, in just_run
    return loop.run_until_complete(coro)
  File "/opt/homebrew/Caskroom/miniconda/base/envs/python310/lib/python3.10/asyncio/base_events.py", line 649, in run_until_complete
    return future.result()
  File "/opt/homebrew/Caskroom/miniconda/base/envs/python310/lib/python3.10/site-packages/nbclient/client.py", line 663, in async_execute
    await self.async_execute_cell(
  File "/opt/homebrew/Caskroom/miniconda/base/envs/python310/lib/python3.10/site-packages/nbclient/client.py", line 965, in async_execute_cell
    await self._check_raise_for_error(cell, cell_index, exec_reply)
  File "/opt/homebrew/Caskroom/miniconda/base/envs/python310/lib/python3.10/site-packages/nbclient/client.py", line 862, in _check_raise_for_error
    raise CellExecutionError.from_cell_and_msg(cell, exec_reply_content)
nbclient.exceptions.CellExecutionError: An error occurred while executing the following cell:
------------------
X_predict = pd.DataFrame(np.linspace(0, 800, 100), columns=['hp'])
y_predict = model.predict(X_predict)

import plotly.graph_objects as go
fig1 = px.scatter(data, x='hp', y='price')
fig2 = px.scatter(x=X_predict['hp'], y=y_predict, name="Prognose")
fig = go.Figure(data = fig1.data + fig2.data)
fig.show()
------------------

[0;31m---------------------------------------------------------------------------[0m
[0;31mTypeError[0m                                 Traceback (most recent call last)
Cell [0;32mIn[14], line 6[0m
[1;32m      4[0m [38;5;28;01mimport[39;00m [38;5;21;01mplotly[39;00m[38;5;21;01m.[39;00m[38;5;21;01mgraph_objects[39;00m [38;5;28;01mas[39;00m [38;5;21;01mgo[39;00m
[1;32m      5[0m fig1 [38;5;241m=[39m px[38;5;241m.[39mscatter(data, x[38;5;241m=[39m[38;5;124m'[39m[38;5;124mhp[39m[38;5;124m'[39m, y[38;5;241m=[39m[38;5;124m'[39m[38;5;124mprice[39m[38;5;124m'[39m)
[0;32m----> 6[0m fig2 [38;5;241m=[39m [43mpx[49m[38;5;241;43m.[39;49m[43mscatter[49m[43m([49m[43mx[49m[38;5;241;43m=[39;49m[43mX_predict[49m[43m[[49m[38;5;124;43m'[39;49m[38;5;124;43mhp[39;49m[38;5;124;43m'[39;49m[43m][49m[43m,[49m[43m [49m[43my[49m[38;5;241;43m=[39;49m[43my_predict[49m[43m,[49m[43m [49m[43mname[49m[38;5;241;43m=[39;49m[38;5;124;43m"[39;49m[38;5;124;43mPrognose[39;49m[38;5;124;43m"[39;49m[43m)[49m
[1;32m      7[0m fig [38;5;241m=[39m go[38;5;241m.[39mFigure(data [38;5;241m=[39m fig1[38;5;241m.[39mdata [38;5;241m+[39m fig2[38;5;241m.[39mdata)
[1;32m      8[0m fig[38;5;241m.[39mshow()

[0;31mTypeError[0m: scatter() got an unexpected keyword argument 'name'
TypeError: scatter() got an unexpected keyword argument 'name'

